<mujoco model="model_learning_1d">
  <compiler angle="radian"/>
  <option timestep="0.01" gravity="0 0 -9.8" iterations="20" integrator="RK4" />
  <!-- <option timestep="0.01" gravity="0 0 -9.8" iterations="20" integrator="RK4" /> -->
  <!-- Copied from PR2 model in GPS. This was necessary to get natural behaviour -->
  <default>
      <!-- <joint armature="0.04" damping="1" limited="true" /> -->
      <joint armature="8.0" damping="1.0" limited="true" />
      <geom friction="0 0 0" density="0.00001" margin="0.002" condim="3"/>
      <!-- <geom friction="0 0 0" density="1000" margin="0.002" condim="3"/> -->
  </default>
  <size njmax="500" nconmax="100" />
  <worldbody>
      <!-- ======================Adding lighting (why is it inside worldbody?)======================== -->
  		<light cutoff="100" diffuse="1 1 1" dir="-0 0 -1.3" directional="true" exponent="1" pos="0 0 1.3" specular=".1 .1 .1"/>
  		<!-- <geom contype="1" conaffinity="0" condim="1" name="floor" pos="0 0 0" rgba="0.8 0.9 0.8 1" size="20 20 .125" type="plane" material="MatPlane"/> -->
      <geom contype="1" conaffinity="0" condim="1" name="floor" pos="0 0 -1" rgba="0.8 0.9 0.8 1" size="20 20 .125" type="plane" material="MatPlane"/>

      <!-- <body name="object" pos="-1.5 -0.5 0.101" > -->
        <body name="object" pos="-3.0 -0.5 0.101" >
          <!-- <geom rgba="0.4 0.5 0.4 1" type="box" size="0.1 0.1 0.1" contype="1" conaffinity="1" condim="1"/> -->
        <geom rgba="0.4 0.5 0.4 1" type="box" size="0.1 0.1 0.1" contype="1" conaffinity="1" condim="1"/>
        <!-- <joint name="obj_slidex" type="slide" pos="0 0 0" axis="1 0 0" range="-10.0 10.0" damping="0.0" /> -->
        <joint name="obj_slidex" type="slide" pos="-1 0 0" axis="1 0 0" range="-10 10" />
      </body>

      <!-- <body name="friction_patch_1" pos="-1.0 -0.5 -0.001"> -->
      <body name="friction_patch_1" pos="2.0 -0.5 -0.001">
        <!-- <geom rgba="0.5 0.6 0.7 1" type="box" size="0.8 0.3 0.0011" contype="0" conaffinity="1" friction="0.001 0 0"/> -->
        <geom rgba="0.5 0.6 0.7 1" type="box" size="1.8 0.3 0.0011" contype="0" conaffinity="1" friction="0 0 0"/>
      </body>
      <!-- <body name="friction_patch_2" pos="2.3 -0.5 -0.001">
        <geom rgba="0.3 0.6 0.7 1" type="box" size="0.8 0.3 0.0011" contype="0" conaffinity="1" friction="0.005 0 0"/>
      </body>
      <body name="obstacle" pos="3.115 -0.5 .1">
        <geom rgba="0.3 0.2 0.7 1" type="box" size="0.03 0.3 0.2" contype="0" conaffinity="1"/>
      </body> -->


    </worldbody>

    <!-- <geom name="fl" rgba="0.3 0.5 0.6 1" type="box" group="1" size="0.168 0.168 0.05" contype="1" conaffinity="1" /> -->
    <!-- ======================Visualizing the world================================== -->
    <asset>
        <texture type="skybox" builtin="gradient" rgb1=".4 .5 .6" rgb2="0 0 0"
            width="100" height="100"/>
        <texture builtin="flat" height="1278" mark="cross" markrgb="1 1 1" name="texgeom" random="0.01" rgb1="0.8 0.6 0.4" rgb2="0.8 0.6 0.4" type="cube" width="127"/>
        <texture builtin="checker" height="100" name="texplane" rgb1="0 0 0" rgb2="0.8 0.8 0.8" type="2d" width="100"/>
        <material name="MatPlane" reflectance="0.01" shininess="1" specular="1" texrepeat="60 60" texture="texplane"/>
        <material name="geom" texture="texgeom" texuniform="true"/>
    </asset>
    <!-- ======================Adding actuactors================================== -->
    <!-- May have to change ctrlrange, is it in radians?
    gearratio as per abb convention													-->
    <actuator>
			<motor ctrllimited="true" ctrlrange="-50.0 50.0" gear="1" joint="obj_slidex"/>
	</actuator>
</mujoco>
